<?xml version="1.0"?>
<robot name="turtlebot_nav" xmlns:xacro="http://ros.org/wiki/xacro">

  <material name="blue">
    <color rgba="0 0 1 1"/>
  </material>
  <material name="black">
    <color rgba="0 0 0 1"/>
  </material>
  <material name="red">
    <color rgba="1 0 0 1"/>
  </material>

  <link name="base_link">
    <visual>
      <geometry>
        <cylinder radius="0.15" length="0.2"/>
      </geometry>
      <origin xyz="0 0 0.1" rpy="0 0 0"/>
      <material name="blue"/>
    </visual>
    <collision>
      <geometry>
        <cylinder radius="0.15" length="0.2"/>
      </geometry>
      <origin xyz="0 0 0.1" rpy="0 0 0"/>
    </collision>
    <inertial>
      <mass value="5.0"/>
      <origin xyz="0 0 0.1"/>
      <inertia ixx="0.1" iyy="0.1" izz="0.1" ixy="0.0" ixz="0.0" iyz="0.0"/>
    </inertial>
  </link>

  <link name="left_wheel">
    <visual>
      <geometry>
        <cylinder radius="0.05" length="0.05"/>
      </geometry>
      <origin xyz="0 0 0" rpy="1.5707 0 0"/>
      <material name="black"/>
    </visual>
    <collision>
      <geometry>
        <cylinder radius="0.05" length="0.05"/>
      </geometry>
      <origin xyz="0 0 0" rpy="1.5707 0 0"/>
    </collision>
    <inertial>
      <mass value="0.1"/>
      <origin xyz="0 0 0"/>
      <inertia ixx="0.001" iyy="0.001" izz="0.001" ixy="0.0" ixz="0.0" iyz="0.0"/>
    </inertial>
  </link>

  <link name="right_wheel">
    <visual>
      <geometry>
        <cylinder radius="0.05" length="0.05"/>
      </geometry>
      <origin xyz="0 0 0" rpy="1.5707 0 0"/>
      <material name="black"/>
    </visual>
    <collision>
      <geometry>
        <cylinder radius="0.05" length="0.05"/>
      </geometry>
      <origin xyz="0 0 0" rpy="1.5707 0 0"/>
    </collision>
    <inertial>
      <mass value="0.1"/>
      <origin xyz="0 0 0"/>
      <inertia ixx="0.001" iyy="0.001" izz="0.001" ixy="0.0" ixz="0.0" iyz="0.0"/>
    </inertial>
  </link>

  <link name="caster_link">
    <visual>
      <geometry>
        <sphere radius="0.03"/>
      </geometry>
      <origin xyz="0 0 0" rpy="0 0 0"/>
      <material name="black"/>
    </visual>
    <collision>
      <geometry>
        <sphere radius="0.03"/>
      </geometry>
    </collision>
    <inertial>
      <mass value="0.05"/>
      <origin xyz="0 0 0"/>
      <inertia ixx="0.0001" iyy="0.0001" izz="0.0001" ixy="0.0" ixz="0.0" iyz="0.0"/>
    </inertial>
  </link>

  <link name="laser_link">
    <visual>
      <geometry>
        <cylinder radius="0.02" length="0.05"/>
      </geometry>
      <origin xyz="0 0 0.025" rpy="0 0 0"/>
      <material name="red"/>
    </visual>
    <inertial>
      <mass value="0.1"/>
      <origin xyz="0 0 0"/>
      <inertia ixx="0.0001" iyy="0.0001" izz="0.0001" ixy="0.0" ixz="0.0" iyz="0.0"/>
    </inertial>
  </link>

  <joint name="left_wheel_joint" type="continuous">
    <parent link="base_link"/>
    <child link="left_wheel"/>
    <origin xyz="0 0.15 0.05" rpy="0 0 0"/>
    <axis xyz="0 1 0"/>
  </joint>

  <joint name="right_wheel_joint" type="continuous">
    <parent link="base_link"/>
    <child link="right_wheel"/>
    <origin xyz="0 -0.15 0.05" rpy="0 0 0"/>
    <axis xyz="0 1 0"/>
  </joint>

  <joint name="caster_joint" type="fixed">
    <parent link="base_link"/>
    <child link="caster_link"/>
    <origin xyz="0.12 0 0" rpy="0 0 0"/>
  </joint>

  <joint name="laser_joint" type="fixed">
    <parent link="base_link"/>
    <child link="laser_link"/>
    <origin xyz="0 0 0.225" rpy="0 0 0"/>
  </joint>

  <gazebo>
    <plugin name='libgazebo_ros_diff_drive' filename='libgazebo_ros_diff_drive.so'>
      <ros>
        <namespace>/</namespace>
        <publish_rate>100</publish_rate>
      </ros>
      <left_joint>left_wheel_joint</left_joint>
      <right_joint>right_wheel_joint</right_joint>
      <wheel_separation>0.3</wheel_separation>
      <wheel_radius>0.05</wheel_radius>
      <wheel_diameter>0.1</wheel_diameter>
      <odometry_frame>odom</odometry_frame>
      <robot_base_frame>base_link</robot_base_frame>
      <publish_odom>true</publish_odom>
      <publish_odom_tf>true</publish_odom_tf>
      <publish_wheel_tf>false</publish_wheel_tf>
      <command_topic>cmd_vel</command_topic>
      <odom_topic>odom</odom_topic>
    </plugin>
  </gazebo>

  <gazebo reference="laser_link">
    <sensor type="ray" name="head_unit_laser">
      <pose>0 0 0 0 0 0</pose>
      <visualize>true</visualize>
      <update_rate>10</update_rate>
      <ray>
        <scan>
          <horizontal>
            <samples>360</samples>
            <resolution>1</resolution>
            <min_angle>-3.14</min_angle>
            <max_angle>3.14</max_angle>
          </horizontal>
        </scan>
        <range>
          <min>0.1</min>
          <max>6.0</max>
          <resolution>0.01</resolution>
        </range>
      </ray>
      <plugin name="gazebo_ros_laser_controller" filename="libgazebo_ros_ray_sensor.so">
        <ros>
          <namespace>/</namespace>
        </ros>
        <topicName>scan</topicName>
        <frameName>laser_link</frameName>
        <output_type>sensor_msgs/LaserScan</output_type>
        <alwaysOn>true</alwaysOn>
      </plugin>
    </sensor>
  </gazebo>

</robot>
